[2022-11-22T15:30:13.861+0000] {taskinstance.py:1165} INFO - Dependencies all met for <TaskInstance: postgres_operators.Create_Table manual__2022-11-22T15:29:11.313334+00:00 [queued]>
[2022-11-22T15:30:13.870+0000] {taskinstance.py:1165} INFO - Dependencies all met for <TaskInstance: postgres_operators.Create_Table manual__2022-11-22T15:29:11.313334+00:00 [queued]>
[2022-11-22T15:30:13.872+0000] {taskinstance.py:1362} INFO - 
--------------------------------------------------------------------------------
[2022-11-22T15:30:13.873+0000] {taskinstance.py:1363} INFO - Starting attempt 2 of 3
[2022-11-22T15:30:13.874+0000] {taskinstance.py:1364} INFO - 
--------------------------------------------------------------------------------
[2022-11-22T15:30:13.886+0000] {taskinstance.py:1383} INFO - Executing <Task(PythonOperator): Create_Table> on 2022-11-22 15:29:11.313334+00:00
[2022-11-22T15:30:13.892+0000] {standard_task_runner.py:55} INFO - Started process 59 to run task
[2022-11-22T15:30:13.896+0000] {standard_task_runner.py:82} INFO - Running: ['***', 'tasks', 'run', 'postgres_operators', 'Create_Table', 'manual__2022-11-22T15:29:11.313334+00:00', '--job-id', '62', '--raw', '--subdir', 'DAGS_FOLDER/dag_with_Connection.py', '--cfg-path', '/tmp/tmp2szok09g']
[2022-11-22T15:30:13.899+0000] {standard_task_runner.py:83} INFO - Job 62: Subtask Create_Table
[2022-11-22T15:30:13.985+0000] {task_command.py:376} INFO - Running <TaskInstance: postgres_operators.Create_Table manual__2022-11-22T15:29:11.313334+00:00 [running]> on host 10ff3b602703
[2022-11-22T15:30:14.054+0000] {taskinstance.py:1592} INFO - Exporting the following env vars:
AIRFLOW_CTX_DAG_OWNER=klein
AIRFLOW_CTX_DAG_ID=postgres_operators
AIRFLOW_CTX_TASK_ID=Create_Table
AIRFLOW_CTX_EXECUTION_DATE=2022-11-22T15:29:11.313334+00:00
AIRFLOW_CTX_TRY_NUMBER=2
AIRFLOW_CTX_DAG_RUN_ID=manual__2022-11-22T15:29:11.313334+00:00
[2022-11-22T15:30:14.056+0000] {taskinstance.py:1851} ERROR - Task failed with exception
Traceback (most recent call last):
  File "/home/airflow/.local/lib/python3.7/site-packages/airflow/operators/python.py", line 175, in execute
    return_value = self.execute_callable()
  File "/home/airflow/.local/lib/python3.7/site-packages/airflow/operators/python.py", line 193, in execute_callable
    return self.python_callable(*self.op_args, **self.op_kwargs)
TypeError: print_name_settings() takes 1 positional argument but 5 were given
[2022-11-22T15:30:14.065+0000] {taskinstance.py:1406} INFO - Marking task as UP_FOR_RETRY. dag_id=postgres_operators, task_id=Create_Table, execution_date=20221122T152911, start_date=20221122T153013, end_date=20221122T153014
[2022-11-22T15:30:14.075+0000] {standard_task_runner.py:105} ERROR - Failed to execute job 62 for task Create_Table (print_name_settings() takes 1 positional argument but 5 were given; 59)
[2022-11-22T15:30:14.109+0000] {local_task_job.py:164} INFO - Task exited with return code 1
[2022-11-22T15:30:14.129+0000] {local_task_job.py:273} INFO - 0 downstream tasks scheduled from follow-on schedule check
