[2022-11-23T08:26:01.403+0000] {taskinstance.py:1165} INFO - Dependencies all met for <TaskInstance: py_name.print_name manual__2022-11-23T08:25:34.286441+00:00 [queued]>
[2022-11-23T08:26:01.421+0000] {taskinstance.py:1165} INFO - Dependencies all met for <TaskInstance: py_name.print_name manual__2022-11-23T08:25:34.286441+00:00 [queued]>
[2022-11-23T08:26:01.424+0000] {taskinstance.py:1362} INFO - 
--------------------------------------------------------------------------------
[2022-11-23T08:26:01.426+0000] {taskinstance.py:1363} INFO - Starting attempt 2 of 4
[2022-11-23T08:26:01.428+0000] {taskinstance.py:1364} INFO - 
--------------------------------------------------------------------------------
[2022-11-23T08:26:01.446+0000] {taskinstance.py:1383} INFO - Executing <Task(PythonOperator): print_name> on 2022-11-23 08:25:34.286441+00:00
[2022-11-23T08:26:01.455+0000] {standard_task_runner.py:55} INFO - Started process 55 to run task
[2022-11-23T08:26:01.464+0000] {standard_task_runner.py:82} INFO - Running: ['***', 'tasks', 'run', 'py_name', 'print_name', 'manual__2022-11-23T08:25:34.286441+00:00', '--job-id', '73', '--raw', '--subdir', 'DAGS_FOLDER/dag_with_Connection.py', '--cfg-path', '/tmp/tmpljsz5riz']
[2022-11-23T08:26:01.467+0000] {standard_task_runner.py:83} INFO - Job 73: Subtask print_name
[2022-11-23T08:26:01.556+0000] {task_command.py:376} INFO - Running <TaskInstance: py_name.print_name manual__2022-11-23T08:25:34.286441+00:00 [running]> on host 10ff3b602703
[2022-11-23T08:26:01.632+0000] {taskinstance.py:1592} INFO - Exporting the following env vars:
AIRFLOW_CTX_DAG_OWNER=klein
AIRFLOW_CTX_DAG_ID=py_name
AIRFLOW_CTX_TASK_ID=print_name
AIRFLOW_CTX_EXECUTION_DATE=2022-11-23T08:25:34.286441+00:00
AIRFLOW_CTX_TRY_NUMBER=2
AIRFLOW_CTX_DAG_RUN_ID=manual__2022-11-23T08:25:34.286441+00:00
[2022-11-23T08:26:01.635+0000] {taskinstance.py:1851} ERROR - Task failed with exception
Traceback (most recent call last):
  File "/home/airflow/.local/lib/python3.7/site-packages/airflow/operators/python.py", line 175, in execute
    return_value = self.execute_callable()
  File "/home/airflow/.local/lib/python3.7/site-packages/airflow/operators/python.py", line 193, in execute_callable
    return self.python_callable(*self.op_args, **self.op_kwargs)
TypeError: print_name_settings() takes 1 positional argument but 5 were given
[2022-11-23T08:26:01.647+0000] {taskinstance.py:1406} INFO - Marking task as UP_FOR_RETRY. dag_id=py_name, task_id=print_name, execution_date=20221123T082534, start_date=20221123T082601, end_date=20221123T082601
[2022-11-23T08:26:01.659+0000] {standard_task_runner.py:105} ERROR - Failed to execute job 73 for task print_name (print_name_settings() takes 1 positional argument but 5 were given; 55)
[2022-11-23T08:26:01.677+0000] {local_task_job.py:164} INFO - Task exited with return code 1
[2022-11-23T08:26:01.710+0000] {local_task_job.py:273} INFO - 0 downstream tasks scheduled from follow-on schedule check
