[2022-11-23T08:25:35.492+0000] {taskinstance.py:1165} INFO - Dependencies all met for <TaskInstance: py_name.print_name manual__2022-11-23T08:25:34.286441+00:00 [queued]>
[2022-11-23T08:25:35.503+0000] {taskinstance.py:1165} INFO - Dependencies all met for <TaskInstance: py_name.print_name manual__2022-11-23T08:25:34.286441+00:00 [queued]>
[2022-11-23T08:25:35.504+0000] {taskinstance.py:1362} INFO - 
--------------------------------------------------------------------------------
[2022-11-23T08:25:35.505+0000] {taskinstance.py:1363} INFO - Starting attempt 1 of 3
[2022-11-23T08:25:35.506+0000] {taskinstance.py:1364} INFO - 
--------------------------------------------------------------------------------
[2022-11-23T08:25:35.518+0000] {taskinstance.py:1383} INFO - Executing <Task(PythonOperator): print_name> on 2022-11-23 08:25:34.286441+00:00
[2022-11-23T08:25:35.525+0000] {standard_task_runner.py:55} INFO - Started process 53 to run task
[2022-11-23T08:25:35.536+0000] {standard_task_runner.py:82} INFO - Running: ['***', 'tasks', 'run', 'py_name', 'print_name', 'manual__2022-11-23T08:25:34.286441+00:00', '--job-id', '72', '--raw', '--subdir', 'DAGS_FOLDER/dag_with_Connection.py', '--cfg-path', '/tmp/tmp8lgmiebw']
[2022-11-23T08:25:35.538+0000] {standard_task_runner.py:83} INFO - Job 72: Subtask print_name
[2022-11-23T08:25:35.610+0000] {task_command.py:376} INFO - Running <TaskInstance: py_name.print_name manual__2022-11-23T08:25:34.286441+00:00 [running]> on host 10ff3b602703
[2022-11-23T08:25:35.680+0000] {taskinstance.py:1592} INFO - Exporting the following env vars:
AIRFLOW_CTX_DAG_OWNER=klein
AIRFLOW_CTX_DAG_ID=py_name
AIRFLOW_CTX_TASK_ID=print_name
AIRFLOW_CTX_EXECUTION_DATE=2022-11-23T08:25:34.286441+00:00
AIRFLOW_CTX_TRY_NUMBER=1
AIRFLOW_CTX_DAG_RUN_ID=manual__2022-11-23T08:25:34.286441+00:00
[2022-11-23T08:25:35.683+0000] {taskinstance.py:1851} ERROR - Task failed with exception
Traceback (most recent call last):
  File "/home/airflow/.local/lib/python3.7/site-packages/airflow/operators/python.py", line 175, in execute
    return_value = self.execute_callable()
  File "/home/airflow/.local/lib/python3.7/site-packages/airflow/operators/python.py", line 193, in execute_callable
    return self.python_callable(*self.op_args, **self.op_kwargs)
TypeError: print_name_settings() takes 1 positional argument but 5 were given
[2022-11-23T08:25:35.692+0000] {taskinstance.py:1406} INFO - Marking task as UP_FOR_RETRY. dag_id=py_name, task_id=print_name, execution_date=20221123T082534, start_date=20221123T082535, end_date=20221123T082535
[2022-11-23T08:25:35.704+0000] {standard_task_runner.py:105} ERROR - Failed to execute job 72 for task print_name (print_name_settings() takes 1 positional argument but 5 were given; 53)
[2022-11-23T08:25:35.752+0000] {local_task_job.py:164} INFO - Task exited with return code 1
[2022-11-23T08:25:35.776+0000] {local_task_job.py:273} INFO - 0 downstream tasks scheduled from follow-on schedule check
