[2022-11-22T14:46:18.856+0000] {taskinstance.py:1165} INFO - Dependencies all met for <TaskInstance: python_dependences.task1 manual__2022-11-22T14:46:17.647270+00:00 [queued]>
[2022-11-22T14:46:18.866+0000] {taskinstance.py:1165} INFO - Dependencies all met for <TaskInstance: python_dependences.task1 manual__2022-11-22T14:46:17.647270+00:00 [queued]>
[2022-11-22T14:46:18.867+0000] {taskinstance.py:1362} INFO - 
--------------------------------------------------------------------------------
[2022-11-22T14:46:18.869+0000] {taskinstance.py:1363} INFO - Starting attempt 1 of 3
[2022-11-22T14:46:18.870+0000] {taskinstance.py:1364} INFO - 
--------------------------------------------------------------------------------
[2022-11-22T14:46:18.882+0000] {taskinstance.py:1383} INFO - Executing <Task(PythonOperator): task1> on 2022-11-22 14:46:17.647270+00:00
[2022-11-22T14:46:18.889+0000] {standard_task_runner.py:55} INFO - Started process 70 to run task
[2022-11-22T14:46:18.893+0000] {standard_task_runner.py:82} INFO - Running: ['***', 'tasks', 'run', 'python_dependences', 'task1', 'manual__2022-11-22T14:46:17.647270+00:00', '--job-id', '12', '--raw', '--subdir', 'DAGS_FOLDER/dag_test_with_python_dependence.py', '--cfg-path', '/tmp/tmp5xu530td']
[2022-11-22T14:46:18.895+0000] {standard_task_runner.py:83} INFO - Job 12: Subtask task1
[2022-11-22T14:46:18.967+0000] {task_command.py:376} INFO - Running <TaskInstance: python_dependences.task1 manual__2022-11-22T14:46:17.647270+00:00 [running]> on host 10ff3b602703
[2022-11-22T14:46:19.038+0000] {taskinstance.py:1592} INFO - Exporting the following env vars:
AIRFLOW_CTX_DAG_OWNER=klein
AIRFLOW_CTX_DAG_ID=python_dependences
AIRFLOW_CTX_TASK_ID=task1
AIRFLOW_CTX_EXECUTION_DATE=2022-11-22T14:46:17.647270+00:00
AIRFLOW_CTX_TRY_NUMBER=1
AIRFLOW_CTX_DAG_RUN_ID=manual__2022-11-22T14:46:17.647270+00:00
[2022-11-22T14:46:19.041+0000] {taskinstance.py:1851} ERROR - Task failed with exception
Traceback (most recent call last):
  File "/home/airflow/.local/lib/python3.7/site-packages/airflow/operators/python.py", line 175, in execute
    return_value = self.execute_callable()
  File "/home/airflow/.local/lib/python3.7/site-packages/airflow/operators/python.py", line 193, in execute_callable
    return self.python_callable(*self.op_args, **self.op_kwargs)
  File "/opt/airflow/dags/dag_test_with_python_dependence.py", line 8, in get_version
    import sklearn
ModuleNotFoundError: No module named 'sklearn'
[2022-11-22T14:46:19.053+0000] {taskinstance.py:1406} INFO - Marking task as UP_FOR_RETRY. dag_id=python_dependences, task_id=task1, execution_date=20221122T144617, start_date=20221122T144618, end_date=20221122T144619
[2022-11-22T14:46:19.065+0000] {standard_task_runner.py:105} ERROR - Failed to execute job 12 for task task1 (No module named 'sklearn'; 70)
[2022-11-22T14:46:19.107+0000] {local_task_job.py:164} INFO - Task exited with return code 1
[2022-11-22T14:46:19.139+0000] {local_task_job.py:273} INFO - 0 downstream tasks scheduled from follow-on schedule check
