[2022-11-25T09:54:20.863+0000] {taskinstance.py:1165} INFO - Dependencies all met for <TaskInstance: Postgres_Data.create_table manual__2022-11-25T09:54:19.370998+00:00 [queued]>
[2022-11-25T09:54:20.874+0000] {taskinstance.py:1165} INFO - Dependencies all met for <TaskInstance: Postgres_Data.create_table manual__2022-11-25T09:54:19.370998+00:00 [queued]>
[2022-11-25T09:54:20.875+0000] {taskinstance.py:1362} INFO - 
--------------------------------------------------------------------------------
[2022-11-25T09:54:20.876+0000] {taskinstance.py:1363} INFO - Starting attempt 1 of 3
[2022-11-25T09:54:20.877+0000] {taskinstance.py:1364} INFO - 
--------------------------------------------------------------------------------
[2022-11-25T09:54:20.889+0000] {taskinstance.py:1383} INFO - Executing <Task(PostgresOperator): create_table> on 2022-11-25 09:54:19.370998+00:00
[2022-11-25T09:54:20.897+0000] {standard_task_runner.py:55} INFO - Started process 88 to run task
[2022-11-25T09:54:20.902+0000] {standard_task_runner.py:82} INFO - Running: ['***', 'tasks', 'run', 'Postgres_Data', 'create_table', 'manual__2022-11-25T09:54:19.370998+00:00', '--job-id', '61', '--raw', '--subdir', 'DAGS_FOLDER/ConnectionTable.py', '--cfg-path', '/tmp/tmppsu7n1xr']
[2022-11-25T09:54:20.904+0000] {standard_task_runner.py:83} INFO - Job 61: Subtask create_table
[2022-11-25T09:54:20.981+0000] {task_command.py:376} INFO - Running <TaskInstance: Postgres_Data.create_table manual__2022-11-25T09:54:19.370998+00:00 [running]> on host 89ee96b17a7e
[2022-11-25T09:54:21.020+0000] {abstractoperator.py:421} ERROR - Exception rendering Jinja template for task 'create_table', field 'sql'. Template: './SQL/CreateDagTable.sql'
Traceback (most recent call last):
  File "/home/airflow/.local/lib/python3.7/site-packages/airflow/models/abstractoperator.py", line 414, in _do_render_template_fields
    seen_oids,
  File "/home/airflow/.local/lib/python3.7/site-packages/airflow/models/abstractoperator.py", line 468, in render_template
    template = jinja_env.get_template(value)
  File "/home/airflow/.local/lib/python3.7/site-packages/jinja2/environment.py", line 1010, in get_template
    return self._load_template(name, globals)
  File "/home/airflow/.local/lib/python3.7/site-packages/jinja2/environment.py", line 969, in _load_template
    template = self.loader.load(self, name, self.make_globals(globals))
  File "/home/airflow/.local/lib/python3.7/site-packages/jinja2/loaders.py", line 126, in load
    source, filename, uptodate = self.get_source(environment, name)
  File "/home/airflow/.local/lib/python3.7/site-packages/jinja2/loaders.py", line 218, in get_source
    raise TemplateNotFound(template)
jinja2.exceptions.TemplateNotFound: ./SQL/CreateDagTable.sql
[2022-11-25T09:54:21.024+0000] {taskinstance.py:1851} ERROR - Task failed with exception
Traceback (most recent call last):
  File "/home/airflow/.local/lib/python3.7/site-packages/airflow/models/taskinstance.py", line 1457, in _run_raw_task
    self._execute_task_with_callbacks(context, test_mode)
  File "/home/airflow/.local/lib/python3.7/site-packages/airflow/models/taskinstance.py", line 1576, in _execute_task_with_callbacks
    task_orig = self.render_templates(context=context)
  File "/home/airflow/.local/lib/python3.7/site-packages/airflow/models/taskinstance.py", line 2199, in render_templates
    original_task.render_template_fields(context)
  File "/home/airflow/.local/lib/python3.7/site-packages/airflow/models/baseoperator.py", line 1193, in render_template_fields
    self._do_render_template_fields(self, self.template_fields, context, jinja_env, set())
  File "/home/airflow/.local/lib/python3.7/site-packages/airflow/utils/session.py", line 75, in wrapper
    return func(*args, session=session, **kwargs)
  File "/home/airflow/.local/lib/python3.7/site-packages/airflow/models/abstractoperator.py", line 414, in _do_render_template_fields
    seen_oids,
  File "/home/airflow/.local/lib/python3.7/site-packages/airflow/models/abstractoperator.py", line 468, in render_template
    template = jinja_env.get_template(value)
  File "/home/airflow/.local/lib/python3.7/site-packages/jinja2/environment.py", line 1010, in get_template
    return self._load_template(name, globals)
  File "/home/airflow/.local/lib/python3.7/site-packages/jinja2/environment.py", line 969, in _load_template
    template = self.loader.load(self, name, self.make_globals(globals))
  File "/home/airflow/.local/lib/python3.7/site-packages/jinja2/loaders.py", line 126, in load
    source, filename, uptodate = self.get_source(environment, name)
  File "/home/airflow/.local/lib/python3.7/site-packages/jinja2/loaders.py", line 218, in get_source
    raise TemplateNotFound(template)
jinja2.exceptions.TemplateNotFound: ./SQL/CreateDagTable.sql
[2022-11-25T09:54:21.039+0000] {taskinstance.py:1406} INFO - Marking task as UP_FOR_RETRY. dag_id=Postgres_Data, task_id=create_table, execution_date=20221125T095419, start_date=20221125T095420, end_date=20221125T095421
[2022-11-25T09:54:21.051+0000] {standard_task_runner.py:105} ERROR - Failed to execute job 61 for task create_table (./SQL/CreateDagTable.sql; 88)
[2022-11-25T09:54:21.076+0000] {local_task_job.py:164} INFO - Task exited with return code 1
[2022-11-25T09:54:21.105+0000] {local_task_job.py:273} INFO - 0 downstream tasks scheduled from follow-on schedule check
