[2022-11-22T14:45:12.699+0000] {taskinstance.py:1165} INFO - Dependencies all met for <TaskInstance: python_dependences.task1 manual__2022-11-22T14:43:09.498283+00:00 [queued]>
[2022-11-22T14:45:12.710+0000] {taskinstance.py:1165} INFO - Dependencies all met for <TaskInstance: python_dependences.task1 manual__2022-11-22T14:43:09.498283+00:00 [queued]>
[2022-11-22T14:45:12.711+0000] {taskinstance.py:1362} INFO - 
--------------------------------------------------------------------------------
[2022-11-22T14:45:12.712+0000] {taskinstance.py:1363} INFO - Starting attempt 3 of 3
[2022-11-22T14:45:12.713+0000] {taskinstance.py:1364} INFO - 
--------------------------------------------------------------------------------
[2022-11-22T14:45:12.727+0000] {taskinstance.py:1383} INFO - Executing <Task(PythonOperator): task1> on 2022-11-22 14:43:09.498283+00:00
[2022-11-22T14:45:12.737+0000] {standard_task_runner.py:55} INFO - Started process 64 to run task
[2022-11-22T14:45:12.743+0000] {standard_task_runner.py:82} INFO - Running: ['***', 'tasks', 'run', 'python_dependences', 'task1', 'manual__2022-11-22T14:43:09.498283+00:00', '--job-id', '9', '--raw', '--subdir', 'DAGS_FOLDER/dag_test_with_python_dependence.py', '--cfg-path', '/tmp/tmpv0in1qgu']
[2022-11-22T14:45:12.745+0000] {standard_task_runner.py:83} INFO - Job 9: Subtask task1
[2022-11-22T14:45:12.815+0000] {task_command.py:376} INFO - Running <TaskInstance: python_dependences.task1 manual__2022-11-22T14:43:09.498283+00:00 [running]> on host 10ff3b602703
[2022-11-22T14:45:12.881+0000] {taskinstance.py:1592} INFO - Exporting the following env vars:
AIRFLOW_CTX_DAG_OWNER=klein
AIRFLOW_CTX_DAG_ID=python_dependences
AIRFLOW_CTX_TASK_ID=task1
AIRFLOW_CTX_EXECUTION_DATE=2022-11-22T14:43:09.498283+00:00
AIRFLOW_CTX_TRY_NUMBER=3
AIRFLOW_CTX_DAG_RUN_ID=manual__2022-11-22T14:43:09.498283+00:00
[2022-11-22T14:45:12.884+0000] {taskinstance.py:1851} ERROR - Task failed with exception
Traceback (most recent call last):
  File "/home/airflow/.local/lib/python3.7/site-packages/airflow/operators/python.py", line 175, in execute
    return_value = self.execute_callable()
  File "/home/airflow/.local/lib/python3.7/site-packages/airflow/operators/python.py", line 193, in execute_callable
    return self.python_callable(*self.op_args, **self.op_kwargs)
  File "/opt/airflow/dags/dag_test_with_python_dependence.py", line 8, in get_version
    import sklearn
ModuleNotFoundError: No module named 'sklearn'
[2022-11-22T14:45:12.895+0000] {taskinstance.py:1406} INFO - Marking task as FAILED. dag_id=python_dependences, task_id=task1, execution_date=20221122T144309, start_date=20221122T144512, end_date=20221122T144512
[2022-11-22T14:45:12.904+0000] {standard_task_runner.py:105} ERROR - Failed to execute job 9 for task task1 (No module named 'sklearn'; 64)
[2022-11-22T14:45:12.955+0000] {local_task_job.py:164} INFO - Task exited with return code 1
[2022-11-22T14:45:12.986+0000] {local_task_job.py:273} INFO - 0 downstream tasks scheduled from follow-on schedule check
